Workbook

Sheet Product Backlog
B1: User Story
A2: Sl # | B2: As a | C2: I want to | D2: So that | E2: Acceptance Criteria | F2: Wireframe Reference
A3: 1 | B3: Logged in Customer | C3: upload a poor quality picture of my skin and press on submit button | D3: I am redirected to the selfie capture page with an error message saying : "Your image is not valid. Take another image with better quality" | E3: [give proper threshold values] 1. Blurry image should be rejected. 2. A low lighting image should be rejected. 3. A low resolution image should be rejected 4. A combination of any/all of the above three should be rejected 4. A proper image should not be rejected
A4: 2 | B4: Logged in Customer | C4: upload an acceptable quality picture of my skin and press on submit button | D4: I can have my skin image analysed for visible skin concerns , be redirected to a questionnaire to give a complete profile of my skin, and finally view my reccomendations page with the following fields: 1. Hello "user_full_name" ! 2. Skin analysis results: Primary Concerns: those detected through the image. | E4: 1. The user must only be allowed to proceed if the uploaded image passes all image-quality checks for blurriness, lighting, and resolution. 2. Once the image passes the quality checks, the image must be submitted to the Visual AI component for skin-concern analysis. 3. After successful Visual AI analysis, the user must be redirected to the skin questionnaire. 4. Detected skin concerns should be from the series: SC0001-SC0019 & SC1001-SC1009 5. If no skin concern is detected(perfectly fit skin) then Skin analysis results should show the following message: "Your skin looks perfect!" 6. If the image contains one or multiple particular skin concerns then, all of those should be shown in the Skin analysis results: Primary Concerns. 7. No other skins concerns should be shown in the Skin analysis results: Primary Concerns other than the ones really existing in the images and questionnaire.
A5: 3 | B5: Logged in Customer | C5: answer the provided questionnaire and press the submit button | D5: I can view my reccomendation page with the following fields: 1. Hello "user_full_name"! 2. Skin analysis results : Primary Concerns : those detected through the combination of skin concerns from both image and questionnaire. 3.Skin analysis results: Skin Type: detected through questionnaire answers. 5. Reccomended for you: Base : selected through questionnaire answers. 6. Reccomended for you : Active Ingredients: those detected through selfie and questionnaire skin concerns. 7. Reccomended for you: Why this formula: explained by LLM for selected actives detected through selfie and questionnaire skin concerns | E5: 1. Detected skin concerns should be from the series: SC0001-SC0019 , SC1001-SC1009 & SC2001-SC2004. 2. If no skin concern is detected(perfectly fit skin) then Skin analysis results should show the following message: "No skin concerns detected." 3.If the image & questionnaire contains one or multiple particular skin concerns then, all of those should be shown in the Skin analysis results: Primary Concerns. 4.No other skins concerns should be shown in the Skin analysis results: Primary Concerns other than the ones really existing in the images and questionnaire. 5. The total formulation must always weigh 100g total. 6. The percentage of actives in formulation must be listed. 7. The formulation explanation must correctly reflect the reason for choosing the actives and bases as per the LLM. 8. The actives and base comprising the reccomended formulation must be compatible with each other.
A6: 4 | B6: Logged in Customer | C6: press the add to cart button | D6: I can add the reccomended formulation to my shopping cart . | E6: 1.Upon add to cart button being clicked, the reccomended formulation should be saved for the user and added to their shopping cart, allowing them to buy later at their convenience. 2. The saved formulation in [1] must exactly match the reccomended formulation.

Sheet Sprint Backlog
A1: SPRINT BACKLOG
A2: Sprint | B2: User Story ID | C2: Work Item | D2: Tasks | E2: T Shirt Sizing | F2: Story Points | G2: Team | H2: Status | I2: Blocker | J2: Scope
A3: 1 | B3: 1 | C3: 1.1 | D3: Receive image from Shopify widget | E3: M | F3: {=_xlfn.SWITCH(E3,"XS",1,"S",2,"M",3,"L",5,"XL",8,"XXL",13,"XXXL",21,"")} -> 3
D4: Validate image file type
D5: Validate image can be decoded/read
D6: Validate image resolution
D7: Calculate image sharpness
D8: Calculate image brightness/lighting
D9: Define/configure blur rejection threshold
D10: Define/configure low-light rejection threshold
D11: Define/configure minimum resolution threshold
C12: 1.2 | D12: Combine all image-quality checks | E12: M | F12: {=_xlfn.SWITCH(E3,"XS",1,"S",2,"M",3,"L",5,"XL",8,"XXL",13,"XXXL",21,"")} -> 3
D13: Reject image if any required quality check fails
D14: Accept image only if all required checks pass
C15: 1.3 | D15: Return image-validation result to frontend | E15: XS
D16: Display "Your image is not valid. Take another image with better quality"
D17: Redirect user back to selfie capture
C18: 1.4 | D18: Test invalid file type | E18: L
D19: Test unreadable image
D20: Test low-resolution image
D21: Test blurry image
D22: Test low-light image
D23: Test combinations of quality failures
D24: Test valid image
D25: Test User Story 1 acceptance criteria
B26: 2 | C26: 2.1 | D26: Redirect user to questionnaire after image passes validation checks. | E26: XS
D27: Store accepted image in skin_image
D28: Associate image with current customer_session
C29: 2.2 | D29: Define Visual AI response JSON schema based on image_detection.json | E29: XS
D30: Define supported image-detectable concern IDs: SC0001–SC0019, SC1001–SC1009
C31: 2.3 | D31: Define Visual AI system prompt | E31: XL | G31: everyone
D32: Define image-analysis instructions
D33: Define skin-concern detection rules
D34: Restrict output to supported concern IDs
D35: Define no-concern behaviour
D36: Require AI explanation for detected concerns
D37: Require JSON-only response
C38: 2.4 | D38: Send accepted image to Visual AI | E38: L
D39: Validate Visual AI response against JSON schema
D40: Validate returned concern IDs
...

Sheet Updated Sprint
A1: SPRINT BACKLOG
A2: Sprint | B2: User Story ID | C2: Work Item | D2: Tasks | E2: T Shirt Sizing | F2: Story Points | G2: Team | H2: Status | I2: Blocker | J2: Scope | K2: Priority
A3: 1 | B3: 1 | C3: 1.1 | D3: Receive image from Shopify widget and pass it to the image-validation service Validate uploaded image filetype before image processing Validate uploaded image can be decoded/read Validate image resolution against the configured minimum resolution. Calculate image sharpness score. Calculate image brightness/lighting score. Define/configure blur rejection threshold Define/configure low-light rejection threshold Define/configure minimum resolution threshold | E3: L | F3: {=_xlfn.SWITCH(E3,"XS",1,"S",2,"M",3,"L",5,"XL",8,"XXL",13,"XXXL",21,"")} -> 5 | G3: Vidit | H3: Done
C4: 1.2 | D4: Combine all image-quality checks into one image-validation API call - POST /image-validation Reject image when any required quality check fails. Accept image only when all required quality checks pass. | E4: M | F4: {=_xlfn.SWITCH(E4,"XS",1,"S",2,"M",3,"L",5,"XL",8,"XXL",13,"XXXL",21,"")} -> 3 | G4: Vidit | H4: Done
C5: 1.3 | D5: Return image-validation result to frontend Display "Your image is not valid. Take another image with better quality" Redirect user back to selfie capture | E5: XS | F5: {=_xlfn.SWITCH(E5,"XS",1,"S",2,"M",3,"L",5,"XL",8,"XXL",13,"XXXL",21,"")} -> 1 | G5: Azad | H5: Done
C6: 1.4 | D6: Test invalid file type Test unreadable image Test low-resolution image Test blurry image Test low-light image Test combinations of quality failures Test valid image Test User Story 1 acceptance criteria | E6: L | F6: {=_xlfn.SWITCH(E6,"XS",1,"S",2,"M",3,"L",5,"XL",8,"XXL",13,"XXXL",21,"")} -> 5 | G6: Everyone | H6: Done
B7: 2 | C7: 2.1 | D7: Store accepted image in skin_image database table. Associate the stored image with the current customer_session database record using the session identifier. Trigger the asynchronous Visual AI image analysis process for the accepted image Redirect user to static questionnaire page immediately after image validation succeeds. | E7: S | F7: {=_xlfn.SWITCH(E7,"XS",1,"S",2,"M",3,"L",5,"XL",8,"XXL",13,"XXXL",21,"")} -> 2 | G7: Vidit | H7: Done
C8: 2.2 | D8: Define Visual AI response JSON schema using image_detection.json as the schema definition. Define the skin_concern_id field in the Visual AI response. Restrict skin_concern_id values to SC0001–SC0019, SC1001–SC1009. | E8: XS | F8: {=_xlfn.SWITCH(E8,"XS",1,"S",2,"M",3,"L",5,"XL",8,"XXL",13,"XXXL",21,"")} -> 1 | G8: Everyone | H8: Done
C9: 2.3 | D9: Define Visual AI system prompt Define image-analysis instructions Define skin-concern detection rules Restrict output to supported concern IDs Define no-concern behaviour Require AI explanation for every detected concerns Require JSON-only response | E9: XL | F9: {=_xlfn.SWITCH(E9,"XS",1,"S",2,"M",3,"L",5,"XL",8,"XXL",13,"XXXL",21,"")} -> 8 | G9: everyone | H9: WiP
C10: 2.4 | D10: Send accepted image to Visual AI API for image analysis Validate Visual AI response against Visual AI response JSON schema Validate every returned skin_concern_id against the supported concern-ID list. Handle duplicate concern IDs before storing the results Handle unsupported concern IDs Handle empty/no-concern response Handle malformed AI response Handle AI/API failure | E10: L | F10: {=_xlfn.SWITCH(E10,"XS",1,"S",2,"M",3,"L",5,"XL",8,"XXL",13,"XXXL",21,"")} -> 5 | G10: Sayan | H10: Done
C11: 2.5 | D11: Store the validated Visual AI result in session_skin_concern_detection database table Store the detected skin_concern_id value in the concern-ID column of session_skin_concern_detection. Store AI-generated explanations in the explanation column against the corresponding skin_concern_id. Store raw Visual AI response JSON in the raw-detection-JSON column Associate each detection record with the current customer_session. | E11: S | F11: {=_xlfn.SWITCH(E11,"XS",1,"S",2,"M",3,"L",5,"XL",8,"XXL",13,"XXXL",21,"")} -> 2 | G11: Vidit | H11: WiP
C12: 2.6 | D12: Create the image analysis reccomendation response JSON. Populate user_full_name from the logged-in customer's user record. Populate Primary Concerns using only validated skin_concern_id values stored from the Visual AI analysis. Return "Your skin looks perfect!" when the validated image concern list is empty. Return the reccomendation response JSON to the Shopify widget frontend. Display user_full_name on the reccomendation page. Display image-detected Primary Concerns on the reccomendation page. | E12: M | F12: {=_xlfn.SWITCH(E12,"XS",1,"S",2,"M",3,"L",5,"XL",8,"XXL",13,"XXXL",21,"")} -> 3 | G12: Azad, Sayan | H12: WiP
C13: 2.7 | D13: Test Visual AI response validation Test supported concern IDs Test unsupported concern IDs Test duplicate concern handling Test multiple detected concerns Test no visible concern Test malformed AI response Test AI/API failure Test asynchronous image analysis flow Test image-based recommendation response Test User Story 2 acceptance criteria | E13: L | F13: {=_xlfn.SWITCH(E13,"XS",1,"S",2,"M",3,"L",5,"XL",8,"XXL",13,"XXXL",21,"")} -> 5 | G13: Everyone | H13: TBD
C14: 2.8 | D14: Generate 10–20 GenAI test images covering different skin tones, ages, and visible skin concerns Test redness detection across different skin tones Test redness detection on a person with black skin Test visible skin concerns on a person below 50 Test multiple visible skin concerns in a single image Test an image containing no visible skin concern Compare Visual AI returned skin_concern_id values against expected test results Verify unsupported concern IDs are not persisted in the session_skin_concern_detection database table | E14: L | F14: {=_xlfn.SWITCH(E14,"XS",1,"S",2,"M",3,"L",5,"XL",8,"XXL",13,"XXXL",21,"")} -> 5 | G14: Everyone | H14: TBD
D15: Total Sprint Story Points | F15: =SUM(F3:F14) -> 45
A16: 2 | B16: 3 | C16: 3.1 | D16: Display questionnaire to user Collect questionnaire answers Validate required questionnaire fields Store questionnaire answers in questionnaire_response Associate questionnaire response with current customer_session Submit questionnaire for LLM analysis
C17: 3.2 | D17: Define questionnaire-analysis LLM prompt Pass questionnaire JSON to LLM Define concern extraction rules Define skin-type extraction Define sensitivity extraction Define questionnaire-only concern handling
C18: 3.3 | D18: Validate LLM response Handle malformed LLM response Handle LLM/API failure Store questionnaire detection result in session_skin_concern_detection Store LLM-generated explanations Store raw detection JSON
C19: 3.4 | D19: Retrieve image-based detection results Retrieve questionnaire-based detection results Match results using skin_concern_id Calculate image_skin_concern_exists OR questionnaire_skin_concern_exists Combine image and questionnaire explanations Store combined result in session_skin_concern Handle concerns detected only from image Handle concerns detected only from questionnaire Handle concerns detected by both Handle no detected concerns Validate final combined concern set
C20: 3.5 | D20: Retrieve combined skin concerns Retrieve relevant concern_benefit mappings Retrieve active_benefit_score data Retrieve applicable bases using questionnaire/session information Check base-active compatibility Produce candidate bases Produce candidate actives
C21: 3.6 | D21: Pass candidate information , along with questionnaire answers to LLM Generate recommended base Generate recommended active ingredients Generate explanation for selected base Generate explanation for selected actives Ensure selected actives address detected concerns Ensure selected actives are compatible with selected base Generate formulation information
C22: 3.7 | D22: Validate LLM recommendation output
C23: 3.8 | D23: Create recommendation_run Store selected base in recommendation_base Store selected actives in recommendation_active Store recommendation explanations Store recommendation scores/ranks where applicable Store final formatted response in recommendation_output
C24: 3.9 | D24: Build final response containing user full name Include combined primary skin concerns Include skin type Include sensitivity level Include recommended base Include recommended active ingredients Include active percentages/quantities Include formulation weight Include formulation explanation Include formulation/recommendation ID Return recommendation response to Shopify widget
C25: 3.1 | D25: Display user name Display primary skin concerns Display "Your skin looks perfect!" when no concern is detected Display skin type Display sensitivity level Display recommended base Display active ingredients Display active percentages Display formulation explanation Display formulation information
C26: 3.11 | D26: Handle no-compatible-recommendation case Handle LLM failure Handle database failure Handle invalid recommendation/formulation Return appropriate frontend error response
C27: 3.12 | D27: Test questionnaire submission Test questionnaire LLM analysis Test concern fusion Test image/questionnaire OR logic Test candidate generation Test base selection Test active selection Test base-active compatibility Test formulation validation Test 100 g formulation requirement Test recommendation persistence Test final recommendation response Test no-concern scenario Test recommendation error handling Test User Story 3 acceptance criteria
B28: 4 | C28: 4.1 | D28: Identify required Shopify cart/API capability Identify Shopify product/variant representing the formulation Define formulation metadata required by Shopify cart Create/test Shopify product or variant
C29: 4.2 | D29: Receive formulation ID from frontend Retrieve saved formulation Verify formulation belongs to the logged-in customer/session Verify formulation is valid Add recommended formulation/product to Shopify cart Attach required formulation metadata Return cart response
C30: 4.3 | D30: Implement Add to Cart button Disable button while request is processing Call Add to Cart API Display successful cart-addition state Handle Add to Cart failure Prevent duplicate submissions
C31: 4.4 | D31: Test formulation ID validation Test customer/formulation ownership Test Shopify cart item creation Test formulation metadata Test successful Add to Cart Test Add to Cart failure Test duplicate submission prevention Test User Story 4 acceptance criteria

Sheet Burndown Chart
A1: Days | B1: Date | C1: Actual Story Points Left | D1: Excepted Story Points Left | E1: Story Points Done
A2: 1 | B2: 46265 | C2: 45 | D2: =('Updated Sprint'!F15)*(1-(A2-1)/8) -> 45 | E2: 1
A3: 2 | B3: 46266 | C3: =('Updated Sprint'!F15)-SUM(E$2:E3) -> 44 | D3: =('Updated Sprint'!F15)*(1-(A3-1)/8) -> 39.375 | E3: 0
A4: 3 | B4: 46267 | C4: =('Updated Sprint'!F15)-SUM(E$2:E4) -> 39 | D4: =('Updated Sprint'!F15)*(1-(A4-1)/8) -> 33.75 | E4: 5
A5: 4 | B5: 46268 | C5: =('Updated Sprint'!F15)-SUM(E$2:E5) -> 39 | D5: =('Updated Sprint'!F15)*(1-(A5-1)/8) -> 28.125 | E5: 0
A6: 5 | B6: 46269 | C6: =('Updated Sprint'!F15)-SUM(E$2:E6) -> 36 | D6: =('Updated Sprint'!F15)*(1-(A6-1)/8) -> 22.5 | E6: 3
A7: 6 | B7: 46272 | C7: =('Updated Sprint'!F15)-SUM(E$2:E7) -> 31 | D7: =('Updated Sprint'!F15)*(1-(A7-1)/8) -> 16.875 | E7: 5
A8: 7 | B8: 46273 | C8: =('Updated Sprint'!F15)-SUM(E$2:E8) -> 31 | D8: =('Updated Sprint'!F15)*(1-(A8-1)/8) -> 11.25 | E8: 0
A9: 8 | B9: 46274 | C9: =('Updated Sprint'!F15)-SUM(E$2:E9) -> 30 | D9: =('Updated Sprint'!F15)*(1-(A9-1)/8) -> 5.625 | E9: 1
A10: 9 | B10: 46275 | C10: =('Updated Sprint'!F15)-SUM(E$2:E10) -> 30 | D10: =('Updated Sprint'!F15)*(1-(A10-1)/8) -> 0 | E10: 0

Sheet T Shirt sizing rules
A1: TSHIRT SIZING
A2: XS | B2: S | C2: M | D2: L | E2: XL | F2: XXL | G2: XXXL
A3: 1 | B3: 2 | C3: =A3+B3 -> 3 | D3: =B3+C3 -> 5 | E3: =C3+D3 -> 8 | F3: =D3+E3 -> 13 | G3: =E3+F3 -> 21
